<?xml version="1.0"?>
<robot xmlns:xacro="http://wiki.ros.org/xacro">
  <!--
    Universal Robots UR5
  -->
  <xacro:macro name="ur5_robot" params="prefix joint_limited
    shoulder_pan_lower_limit:=${-pi} shoulder_pan_upper_limit:=${pi}
    shoulder_lift_lower_limit:=${-pi} shoulder_lift_upper_limit:=${pi}
    elbow_joint_lower_limit:=${-pi} elbow_joint_upper_limit:=${pi}
    wrist_1_lower_limit:=${-pi} wrist_1_upper_limit:=${pi}
    wrist_2_lower_limit:=${-pi} wrist_2_upper_limit:=${pi}
    wrist_3_lower_limit:=${-pi} wrist_3_upper_limit:=${pi}
    transmission_hw_interface:=hardware_interface/PositionJointInterface
    safety_limits:=false safety_pos_margin:=0.15
    safety_k_position:=20">

    <!-- Inertia parameters -->
    <xacro:property name="base_mass" value="4.0" />
    <xacro:property name="shoulder_mass" value="3.7000" />
    <xacro:property name="upper_arm_mass" value="8.3930" />
    <xacro:property name="forearm_mass" value="2.2750" />
    <xacro:property name="wrist_1_mass" value="1.2190" />
    <xacro:property name="wrist_2_mass" value="1.2190" />
    <xacro:property name="wrist_3_mass" value="0.1879" />

    <!-- Link offsets -->
    <xacro:property name="shoulder_y_offset" value="0.089159" />
    <xacro:property name="upper_arm_y_offset" value="-0.13625" />
    <xacro:property name="forearm_y_offset" value="-0.1197" />
    <xacro:property name="wrist_1_z_offset" value="0.093" />
    <xacro:property name="wrist_2_z_offset" value="0.0" />
    <xacro:property name="wrist_3_z_offset" value="0.0" />
    <xacro:property name="wrist_3_length" value="0.0" />

    <!-- Joint limits -->
    <xacro:property name="shoulder_pan_velocity" value="3.15" />
    <xacro:property name="shoulder_lift_velocity" value="3.15" />
    <xacro:property name="elbow_velocity" value="3.15" />
    <xacro:property name="wrist_1_velocity" value="3.2" />
    <xacro:property name="wrist_2_velocity" value="3.2" />
    <xacro:property name="wrist_3_velocity" value="3.2" />

    <!-- Base link -->
    <link name="${prefix}base_link">
      <visual>
        <geometry>
          <mesh filename="package://ur5_description/meshes/ur5/visual/base.dae"/>
        </geometry>
      </visual>
      <collision>
        <geometry>
          <mesh filename="package://ur5_description/meshes/ur5/collision/base.stl"/>
        </geometry>
      </collision>
      <inertial>
        <mass value="${base_mass}"/>
        <origin xyz="0 0 0" rpy="0 0 0"/>
        <inertia ixx="0.00443333156" ixy="0.0" ixz="0.0" iyy="0.00443333156" iyz="0.0" izz="0.0072"/>
      </inertial>
    </link>

    <!-- Shoulder link -->
    <link name="${prefix}shoulder_link">
      <visual>
        <geometry>
          <mesh filename="package://ur5_description/meshes/ur5/visual/shoulder.dae"/>
        </geometry>
      </visual>
      <collision>
        <geometry>
          <mesh filename="package://ur5_description/meshes/ur5/collision/shoulder.stl"/>
        </geometry>
      </collision>
      <inertial>
        <mass value="${shoulder_mass}"/>
        <origin xyz="0 0 0" rpy="0 0 0"/>
        <inertia ixx="0.010267495893" ixy="0.0" ixz="0.0" iyy="0.010267495893" iyz="0.0" izz="0.00666"/>
      </inertial>
    </link>

    <!-- Upper arm link -->
    <link name="${prefix}upper_arm_link">
      <visual>
        <geometry>
          <mesh filename="package://ur5_description/meshes/ur5/visual/upperarm.dae"/>
        </geometry>
      </visual>
      <collision>
        <geometry>
          <mesh filename="package://ur5_description/meshes/ur5/collision/upperarm.stl"/>
        </geometry>
      </collision>
      <inertial>
        <mass value="${upper_arm_mass}"/>
        <origin xyz="0 ${upper_arm_y_offset} 0" rpy="0 0 0"/>
        <inertia ixx="0.133886" ixy="0.0" ixz="0.0" iyy="0.0151074" iyz="0.0" izz="0.13774"/>
      </inertial>
    </link>

    <!-- Forearm link -->
    <link name="${prefix}forearm_link">
      <visual>
        <geometry>
          <mesh filename="package://ur5_description/meshes/ur5/visual/forearm.dae"/>
        </geometry>
      </visual>
      <collision>
        <geometry>
          <mesh filename="package://ur5_description/meshes/ur5/collision/forearm.stl"/>
        </geometry>
      </collision>
      <inertial>
        <mass value="${forearm_mass}"/>
        <origin xyz="0 ${forearm_y_offset} 0" rpy="0 0 0"/>
        <inertia ixx="0.0311898" ixy="0.0" ixz="0.0" iyy="0.004095" iyz="0.0" izz="0.0311898"/>
      </inertial>
    </link>

    <!-- Wrist 1 link -->
    <link name="${prefix}wrist_1_link">
      <visual>
        <geometry>
          <mesh filename="package://ur5_description/meshes/ur5/visual/wrist1.dae"/>
        </geometry>
      </visual>
      <collision>
        <geometry>
          <mesh filename="package://ur5_description/meshes/ur5/collision/wrist1.stl"/>
        </geometry>
      </collision>
      <inertial>
        <mass value="${wrist_1_mass}"/>
        <origin xyz="0 ${wrist_1_z_offset} 0" rpy="0 0 0"/>
        <inertia ixx="0.0025599" ixy="0.0" ixz="0.0" iyy="0.000792168" iyz="0.0" izz="0.0025599"/>
      </inertial>
    </link>

    <!-- Wrist 2 link -->
    <link name="${prefix}wrist_2_link">
      <visual>
        <geometry>
          <mesh filename="package://ur5_description/meshes/ur5/visual/wrist2.dae"/>
        </geometry>
      </visual>
      <collision>
        <geometry>
          <mesh filename="package://ur5_description/meshes/ur5/collision/wrist2.stl"/>
        </geometry>
      </collision>
      <inertial>
        <mass value="${wrist_2_mass}"/>
        <origin xyz="0 ${wrist_2_z_offset} 0" rpy="0 0 0"/>
        <inertia ixx="0.0025599" ixy="0.0" ixz="0.0" iyy="0.000792168" iyz="0.0" izz="0.0025599"/>
      </inertial>
    </link>

    <!-- Wrist 3 link -->
    <link name="${prefix}wrist_3_link">
      <visual>
        <geometry>
          <mesh filename="package://ur5_description/meshes/ur5/visual/wrist3.dae"/>
        </geometry>
      </visual>
      <collision>
        <geometry>
          <mesh filename="package://ur5_description/meshes/ur5/collision/wrist3.stl"/>
        </geometry>
      </collision>
      <inertial>
        <mass value="${wrist_3_mass}"/>
        <origin xyz="0 ${wrist_3_z_offset} 0" rpy="0 0 0"/>
        <inertia ixx="0.000132134" ixy="0.0" ixz="0.0" iyy="0.000132134" iyz="0.0" izz="0.00021942"/>
      </inertial>
    </link>

    <!-- Joints -->
    <joint name="${prefix}shoulder_pan_joint" type="revolute">
      <parent link="${prefix}base_link"/>
      <child link="${prefix}shoulder_link"/>
      <origin xyz="0 0 0.089159" rpy="0 0 0"/>
      <axis xyz="0 0 1"/>
      <limit lower="${shoulder_pan_lower_limit}" upper="${shoulder_pan_upper_limit}"
             effort="150.0" velocity="${shoulder_pan_velocity}"/>
      <xacro:if value="${safety_limits}">
        <safety_controller soft_lower_limit="${shoulder_pan_lower_limit + safety_pos_margin}"
                          soft_upper_limit="${shoulder_pan_upper_limit - safety_pos_margin}"
                          k_position="${safety_k_position}" k_velocity="0.0"/>
      </xacro:if>
      <dynamics damping="0" friction="0"/>
    </joint>

    <joint name="${prefix}shoulder_lift_joint" type="revolute">
      <parent link="${prefix}shoulder_link"/>
      <child link="${prefix}upper_arm_link"/>
      <origin xyz="0 ${shoulder_y_offset} 0" rpy="0 ${pi/2} 0"/>
      <axis xyz="0 0 1"/>
      <limit lower="${shoulder_lift_lower_limit}" upper="${shoulder_lift_upper_limit}"
             effort="150.0" velocity="${shoulder_lift_velocity}"/>
      <xacro:if value="${safety_limits}">
        <safety_controller soft_lower_limit="${shoulder_lift_lower_limit + safety_pos_margin}"
                          soft_upper_limit="${shoulder_lift_upper_limit - safety_pos_margin}"
                          k_position="${safety_k_position}" k_velocity="0.0"/>
      </xacro:if>
      <dynamics damping="0" friction="0"/>
    </joint>

    <joint name="${prefix}elbow_joint" type="revolute">
      <parent link="${prefix}upper_arm_link"/>
      <child link="${prefix}forearm_link"/>
      <origin xyz="0 ${upper_arm_y_offset} 0" rpy="0 0 0"/>
      <axis xyz="0 0 1"/>
      <limit lower="${elbow_joint_lower_limit}" upper="${elbow_joint_upper_limit}"
             effort="150.0" velocity="${elbow_velocity}"/>
      <xacro:if value="${safety_limits}">
        <safety_controller soft_lower_limit="${elbow_joint_lower_limit + safety_pos_margin}"
                          soft_upper_limit="${elbow_joint_upper_limit - safety_pos_margin}"
                          k_position="${safety_k_position}" k_velocity="0.0"/>
      </xacro:if>
      <dynamics damping="0" friction="0"/>
    </joint>

    <joint name="${prefix}wrist_1_joint" type="revolute">
      <parent link="${prefix}forearm_link"/>
      <child link="${prefix}wrist_1_link"/>
      <origin xyz="0 ${forearm_y_offset} 0" rpy="0 0 0"/>
      <axis xyz="0 0 1"/>
      <limit lower="${wrist_1_lower_limit}" upper="${wrist_1_upper_limit}"
             effort="28.0" velocity="${wrist_1_velocity}"/>
      <xacro:if value="${safety_limits}">
        <safety_controller soft_lower_limit="${wrist_1_lower_limit + safety_pos_margin}"
                          soft_upper_limit="${wrist_1_upper_limit - safety_pos_margin}"
                          k_position="${safety_k_position}" k_velocity="0.0"/>
      </xacro:if>
      <dynamics damping="0" friction="0"/>
    </joint>

    <joint name="${prefix}wrist_2_joint" type="revolute">
      <parent link="${prefix}wrist_1_link"/>
      <child link="${prefix}wrist_2_link"/>
      <origin xyz="0 0 ${wrist_1_z_offset}" rpy="0 ${pi/2} 0"/>
      <axis xyz="0 0 1"/>
      <limit lower="${wrist_2_lower_limit}" upper="${wrist_2_upper_limit}"
             effort="28.0" velocity="${wrist_2_velocity}"/>
      <xacro:if value="${safety_limits}">
        <safety_controller soft_lower_limit="${wrist_2_lower_limit + safety_pos_margin}"
                          soft_upper_limit="${wrist_2_upper_limit - safety_pos_margin}"
                          k_position="${safety_k_position}" k_velocity="0.0"/>
      </xacro:if>
      <dynamics damping="0" friction="0"/>
    </joint>

    <joint name="${prefix}wrist_3_joint" type="revolute">
      <parent link="${prefix}wrist_2_link"/>
      <child link="${prefix}wrist_3_link"/>
      <origin xyz="0 0 ${wrist_2_z_offset}" rpy="0 0 0"/>
      <axis xyz="0 0 1"/>
      <limit lower="${wrist_3_lower_limit}" upper="${wrist_3_upper_limit}"
             effort="28.0" velocity="${wrist_3_velocity}"/>
      <xacro:if value="${safety_limits}">
        <safety_controller soft_lower_limit="${wrist_3_lower_limit + safety_pos_margin}"
                          soft_upper_limit="${wrist_3_upper_limit - safety_pos_margin}"
                          k_position="${safety_k_position}" k_velocity="0.0"/>
      </xacro:if>
      <dynamics damping="0" friction="0"/>
    </joint>

    <!-- Tool frame -->
    <link name="${prefix}tool0"/>
    <joint name="${prefix}tool0_joint" type="fixed">
      <parent link="${prefix}wrist_3_link"/>
      <child link="${prefix}tool0"/>
      <origin xyz="0 0 ${wrist_3_length}" rpy="0 ${pi/2} ${pi/2}"/>
    </joint>

  </xacro:macro>
</robot>
